<mujoco model="humanoid">

  <statistic extent="2" center="0 0 1"/>

  <option timestep="0.00555"/>

  <default>
    <motor ctrlrange="-1 1" ctrllimited="true"/>
    <default class="body">
      <geom  type="capsule" condim="1" friction="1.0 0.05 0.05" solimp=".9 .99 .003" solref=".015 1" material="self"/>
      <joint type="hinge" damping="0.1" stiffness="5" armature=".007" limited="true" solimplimit="0 .99 .01"/>
      <default class="small_joint">
        <joint damping="1.0" stiffness="2" armature=".006"/>
      </default>
      <default class="big_joint">
        <joint damping="5" stiffness="10" armature=".01"/>
      </default>
      <default class="bigger_stiff_joint">
        <joint damping="5" stiffness="20" armature=".01"/>
      </default>
      <default class="big_stiff_joint">
        <joint damping="5" stiffness="20" armature=".02"/>
      </default>
      <site size=".04" group="3"/>
      <default class="force-torque">
        <site type="box" size=".01 .01 .02" rgba="1 0 0 1" />
      </default>
      <default class="touch">
        <site type="capsule" rgba="0 0 1 .3"/>
      </default>
    </default>
  </default>

  <worldbody>

    <body name="torso" pos="0 0 1.5" childclass="body">
      <light name="top" pos="0 0 2" mode="trackcom"/>
      <camera name="back" pos="-3 0 1" xyaxes="0 -1 0 1 0 2" mode="trackcom"/>
      <camera name="side" pos="0 -3 1" xyaxes="1 0 0 0 1 2" mode="trackcom"/>
      <freejoint name="root"/>
      <site name="root" class="force-torque"/>
      <geom name="torso" fromto="0 -.07 0 0 .07 0" size=".07"/>
      <geom name="upper_waist" fromto="-.01 -.06 -.12 -.01 .06 -.12" size=".06"/>
      <site name="torso" class="touch" type="box" pos="0 0 -.05" size=".075 .14 .13"/>
      <body name="head" pos="0 0 .19">
        <geom name="head" type="sphere" size=".09"/>
        <site name="head" class="touch" type="sphere" size=".091"/>
        <camera name="egocentric" pos=".09 0 0" xyaxes="0 -1 0 .1 0 1" fovy="80"/>
      </body>

      <body name="right_upper_arm" pos="0 -.17 .06">
        <joint name="right_shoulder1" axis="2 1 1"  range="-90 70" class="big_joint"/>
        <joint name="right_shoulder2" axis="0 -1 1" range="-90 70" class="big_joint"/>
        <geom name="right_upper_arm" fromto="0 0 0 .16 -.16 -.16" size=".04 .16"/>
        <site name="right_upper_arm" class="touch" pos=".08 -.08 -.08" size=".041 .14" zaxis="1 -1 -1"/>
        <body name="right_lower_arm" pos=".18 -.18 -.18">
          <joint name="right_elbow" axis="0 -1 1" range="-90 50" class="small_joint"/>
          <geom name="right_lower_arm" fromto=".01 .01 .01 .17 .17 .17" size=".031"/>
          <site name="right_lower_arm" class="touch" pos=".09 .09 .09" size=".032 .14" zaxis="1 1 1"/>
          <!-- <body name="right_hand" pos=".18 .18 .18"> -->
            <!-- <geom name="right_hand" type="sphere" size=".04"/> -->
            <!-- <site name="right_hand" class="touch" type="sphere" size=".041"/> -->
          <!-- </body> -->

          <body name="right_hook" pos=".18 .18 .18">
            <geom name="right_hook_seg_1" type="capsule" size="0.005" fromto="0.01 0.01 0.01 .015 .015 .015"/>
            <geom name="right_hook_seg_2" type="capsule" size="0.0045" fromto=".015 .015 .015 -.0 .025 .05"/>
            <geom name="right_hook_seg_3" type="capsule" size="0.0035" fromto="-.0 .025 .05 .05 .05 .05"/>
            <geom name="right_hook_seg_4" type="capsule" size="0.0025" fromto=".05 .05 .05 .035 .035 .035"/>
          </body>

        </body>
      </body>

      <body name="left_upper_arm" pos="0 .17 .06">
        <joint name="left_shoulder1" axis="-2 1 -1" range="-90 70" class="big_joint"/>
        <joint name="left_shoulder2" axis="0 -1 -1" range="-90 70" class="big_joint"/>
        <geom name="left_upper_arm" fromto="0 0 0 .16 .16 -.16" size=".04 .16"/>
        <site name="left_upper_arm" class="touch" pos=".08 .08 -.08" size=".041 .14" zaxis="1 1 -1"/>
        <body name="left_lower_arm" pos=".18 .18 -.18">
          <joint name="left_elbow" axis="0 -1 -1" range="-90 50" class="small_joint"/>
          <geom name="left_lower_arm" fromto=".01 -.01 .01 .17 -.17 .17" size=".031"/>
          <site name="left_lower_arm" class="touch" pos=".09 -.09 .09" size=".032 .14" zaxis="1 -1 1"/>
          <!-- <body name="left_hand" pos=".18 -.18 .18"> -->
            <!-- <geom name="left_hand" type="sphere" size=".04"/> -->
            <!-- <site name="left_hand" class="touch" type="sphere" size=".041"/> -->
          <!-- </body> -->

          <body name="left_hook" pos=".18 -.18 .18">
            <geom name="left_hook_seg_1" type="capsule" size="0.005" fromto="0.01 -0.01 0.01 .015 -.015 .015"/>
            <geom name="left_hook_seg_2" type="capsule" size="0.0045" fromto=".015 -.015 .015 -.0 -.025 .05"/>
            <geom name="left_hook_seg_3" type="capsule" size="0.0035" fromto="-.0 -.025 .05 .05 -.05 .05"/>
            <geom name="left_hook_seg_4" type="capsule" size="0.0025" fromto=".05 -.05 .05 .035 -.035 .035"/>
          </body>


        </body>
      </body>

    </body>
  </worldbody>

  <actuator>
    <motor name='right_shoulder1' gear='67.5' joint='right_shoulder1'/>
    <motor name='right_shoulder2' gear='67.5' joint='right_shoulder2'/>
    <motor name='right_elbow'     gear='45.0' joint='right_elbow'/>  
    <motor name='left_shoulder1'  gear='67.5' joint='left_shoulder1'/>
    <motor name='left_shoulder2'  gear='67.5' joint='left_shoulder2'/>
    <motor name='left_elbow'      gear='45.0' joint='left_elbow'/>
  </actuator>

  <sensor>
    <subtreelinvel name="torso_subtreelinvel" body="torso"/>
    <accelerometer name="torso_accel"    site="root"/>
    <velocimeter name="torso_vel"        site="root"/>
    <gyro name="torso_gyro"              site="root"/>

    <touch name="torso_touch"            site="torso"/>
    <touch name="head_touch"             site="head"/>
    <touch name="right_upper_arm_touch"  site="right_upper_arm"/>
    <touch name="right_lower_arm_touch"  site="right_lower_arm"/>
    <touch name="right_hand_touch"       site="right_hand"/>
    <touch name="left_upper_arm_touch"   site="left_upper_arm"/>
    <touch name="left_lower_arm_touch"   site="left_lower_arm"/>
    <touch name="left_hand_touch"        site="left_hand"/>
  </sensor>

</mujoco>
