<robot name="dumpUrdf">
	<link name="chest" >
		<inertial>
			<origin rpy = "0 0 0" xyz = "0.000000 0.0 0.000000" />
			<mass value = "14.000000" />
			<inertia ixx = "0.1" ixy = "0" ixz = "0" iyy = "0.1" iyz = "0" izz = "0.1" />
		</inertial>
		<collision>
			<origin rpy = "0 0 0" xyz = "0.000000 0.0 0.000000" />
			<geometry>
				<box size="1 1 1" />
			</geometry>
		</collision>
	</link>

	<link name="right_shoulder" >
		<inertial>
			<origin rpy = "0 0 0" xyz = "0.000000 -0.560000 0.000000" />
			<mass value = "1.500000" />
			<inertia ixx = "0.1" ixy = "0" ixz = "0" iyy = "0.1" iyz = "0" izz = "0.1" />
		</inertial>
		<collision>
			<origin rpy = "-1.570796 0 0" xyz = "0.000000 -0.560000 0.000000" />
			<geometry>
				<capsule length="0.720000" radius="0.180000"/>
			</geometry>
		</collision>
	</link>
	<joint name="right_shoulder" type="spherical" >
		<parent link="chest" />
		<child link="right_shoulder" />
		<origin rpy = "0 0 0" xyz = "-0.096200 0.974000 0.732440" />
		<!-- Axis just here to suppress URDF errors, this gets overwritten in code-->
		<axis xyz="0.00000 0.00000 0.00000"/>
	</joint>
	<link name="right_elbow" >
		<inertial>
			<origin rpy = "0 0 0" xyz = "0.000000 -0.480000 0.000000" />
			<mass value = "1.000000" />
			<inertia ixx = "0.1" ixy = "0" ixz = "0" iyy = "0.1" iyz = "0" izz = "0.1" />
		</inertial>
		<collision>
			<origin rpy = "-1.570796 0 0" xyz = "0.000000 -0.480000 0.000000" />
			<geometry>
				<capsule length="0.540000" radius="0.160000"/>
			</geometry>
		</collision>
	</link>
	<joint name="right_elbow" type="revolute" >
		<parent link="right_shoulder" />
		<child link="right_elbow" />
		<limit effort="1000.0" lower="0" upper="3.14" velocity="0.5"/>
		<origin rpy = "0 0 0" xyz = "0.000000 -1.099152 0.000000" />
		<axis xyz = "0.000000 0.000000 1.000000" />
	</joint>
	<link name="right_wrist" >
		<inertial>
			<origin rpy = "0 0 0" xyz = "0.000000 0.000000 0.000000" />
			<mass value = "0.500000" />
			<inertia ixx = "0.1" ixy = "0" ixz = "0" iyy = "0.1" iyz = "0" izz = "0.1" />
		</inertial>
		<collision>
			<origin rpy = "0 0 0" xyz = "0.000000 0.000000 0.000000" />
			<geometry>
				<sphere radius = "0.160000" />
			</geometry>
		</collision>
	</link>
	<joint name="right_wrist" type="fixed" >
		<parent link="right_elbow" />
		<child link="right_wrist" />
		<origin rpy = "0 0 0" xyz = "0.000000 -1.035788 0.000000" />
	</joint>

	<link name="left_shoulder" >
		<inertial>
			<origin rpy = "0 0 0" xyz = "0.000000 -0.560000 0.000000" />
			<mass value = "1.500000" />
			<inertia ixx = "0.1" ixy = "0" ixz = "0" iyy = "0.1" iyz = "0" izz = "0.1" />
		</inertial>
		<collision>
			<origin rpy = "-1.570796 0 0" xyz = "0.000000 -0.560000 0.000000" />
			<geometry>
				<capsule length="0.720000" radius="0.180000"/>
			</geometry>
		</collision>
	</link>
	<joint name="left_shoulder" type="spherical" >
		<parent link="chest" />
		<child link="left_shoulder" />
		<origin rpy = "0 0 0" xyz = "-0.096200 0.974000 -0.732440" />
		<!-- Axis just here to suppress URDF errors, this gets overwritten in code-->
		<axis xyz="0.00000 0.00000 0.00000"/>
	</joint>
	<link name="left_elbow" >
		<inertial>
			<origin rpy = "0 0 0" xyz = "0.000000 -0.480000 0.000000" />
			<mass value = "1.000000" />
			<inertia ixx = "0.1" ixy = "0" ixz = "0" iyy = "0.1" iyz = "0" izz = "0.1" />
		</inertial>
		<collision>
			<origin rpy = "-1.570796 0 0" xyz = "0.000000 -0.480000 0.000000" />
			<geometry>
				<capsule length="0.540000" radius="0.160000"/>
			</geometry>
		</collision>
	</link>
	<joint name="left_elbow" type="revolute" >
		<parent link="left_shoulder" />
		<child link="left_elbow" />
		<limit effort="1000.0" lower="0" upper="3.14" velocity="0.5"/>
		<origin rpy = "0 0 0" xyz = "0.000000 -1.099152 0.000000" />
		<axis xyz = "0.000000 0.000000 1.000000" />
	</joint>
	<link name="left_wrist" >
		<inertial>
			<origin rpy = "0 0 0" xyz = "0.000000 0.000000 0.000000" />
			<mass value = "0.500000" />
			<inertia ixx = "0.1" ixy = "0" ixz = "0" iyy = "0.1" iyz = "0" izz = "0.1" />
		</inertial>
		<collision>
			<origin rpy = "0 0 0" xyz = "0.000000 0.000000 0.000000" />
			<geometry>
				<sphere radius = "0.160000" />
			</geometry>
		</collision>
	</link>
	<joint name="left_wrist" type="fixed" >
		<parent link="left_elbow" />
		<child link="left_wrist" />
		<origin rpy = "0 0 0" xyz = "0.000000 -1.035788 0.000000" />
	</joint>

	<link name="left_hand_tip">
		<inertial>
			<origin rpy = "0 0 0" xyz = "0.000000 0.000000 0.000000" />
			<mass value = "0.0" />
			<inertia ixx = "0.0" ixy = "0" ixz = "0" iyy = "0.1" iyz = "0" izz = "0.0" />
		</inertial>
		<visual>
			<origin rpy = "0 0 0" xyz = "0.000000 0.000000 0.000000" />
			<geometry>
				<sphere radius = "0.10000" />
			</geometry>
		</visual>
	</link>
	<joint name="left_hand" type="fixed" >
		<parent link="left_wrist" />
		<child link="left_hand_tip" />
		<origin rpy = "0 0 0" xyz = "0.000000 -0.2 0.000000" />
	</joint>

	<link name="right_hand_tip">
		<inertial>
			<origin rpy = "0 0 0" xyz = "0.000000 0.000000 0.000000" />
			<mass value = "0.0" />
			<inertia ixx = "0.0" ixy = "0" ixz = "0" iyy = "0.1" iyz = "0" izz = "0.0" />
		</inertial>
		<visual>
			<origin rpy = "0 0 0" xyz = "0.000000 0.000000 0.000000" />
			<geometry>
				<sphere radius = "0.10000" />
			</geometry>
		</visual>
	</link>
	<joint name="right_hand" type="fixed" >
		<parent link="right_wrist" />
		<child link="right_hand_tip" />
		<origin rpy = "0 0 0" xyz = "0.000000 -0.2 0.000000" />
	</joint>
</robot>
