<!-- 
Mujoco models
This work is derived from MuJuCo models used under the following license:

This file is part of MuJoCo.     
Copyright 2009-2015 Roboti LLC.	
Mujoco		:: Advanced physics simulation engine
Source		: www.roboti.us
Version		: 1.31
Released 	: 23Apr16
Author		:: Vikash Kumar
Contacts 	: kumar@roboti.us 
-->

<mujoco model='humanoid'>
    <compiler inertiafromgeom='true' angle='degree'/>

    <default>
        <joint limited='true' damping='1' armature='0' />
        <geom contype='1' conaffinity='1' condim='1' rgba='0.8 0.6 .4 1'
        	margin="0.001" solref=".02 1" solimp=".8 .8 .01" material="geom"/>
        <motor ctrlrange='-.4 .4' ctrllimited='true'/>
    </default>

    <option timestep='0.002' iterations="50" solver="PGS">
        <flag energy="enable"/>
    </option>


    <worldbody>

        <body name='torso' pos='0 0 1.4'>
            <light mode='trackcom' directional='false' diffuse='.8 .8 .8' specular='0.3 0.3 0.3' pos='0 0 4.0' dir='0 0 -1'/>
            
            <geom name='torso1' type='capsule' fromto='0 -.07 0 0 .07 0'  size='0.07' />

            <body name='right_upper_arm' pos='0 -0.17 0.06' >
                <joint name='right_shoulder1' type='hinge' pos='0 0 0' axis='2 1 1'  range='-85 60' stiffness='1' armature='0.0068' />
                <joint name='right_shoulder2' type='hinge' pos='0 0 0' axis='0 -1 1' range='-85 60' stiffness='1'  armature='0.0051' />
                <geom name='right_uarm1' type='capsule' fromto='0 0 0 .16 -.16 -.16'  size='0.04 0.16' />
                <body name='right_lower_arm' pos='.18 -.18 -.18' >
                    <joint name='right_elbow' type='hinge' pos='0 0 0' axis='0 -1 1' range='-90 50'  stiffness='0' armature='0.0028' />
                    <geom name='right_larm' type='capsule' fromto='0.01 0.01 0.01 .17 .17 .17'  size='0.031' />
                    <geom name='right_hand' type='sphere' pos='.18 .18 .18'  size='0.04'/>
                </body>
            </body>
            <body name='left_upper_arm' pos='0 0.17 0.06' >
                <joint name='left_shoulder1' type='hinge' pos='0 0 0' axis='2 -1 1' range='-60 85' stiffness='1' armature='0.0068' />
                <joint name='left_shoulder2' type='hinge' pos='0 0 0' axis='0 1 1' range='-60 85'  stiffness='1' armature='0.0051' />
                <geom name='left_uarm1' type='capsule' fromto='0 0 0 .16 .16 -.16'  size='0.04 0.16' />
                <body name='left_lower_arm' pos='.18 .18 -.18' >
                    <joint name='left_elbow' type='hinge' pos='0 0 0' axis='0 -1 -1' range='-90 50' stiffness='0' armature='0.0028' />
                    <geom name='left_larm' type='capsule' fromto='0.01 -0.01 0.01 .17 -.17 .17'  size='0.031' />
                    <geom name='left_hand' type='sphere' pos='.18 -.18 .18'  size='0.04'/>
                </body>
            </body>
        </body>
    </worldbody>

    <actuator>
        <motor name='right_shoulder1' gear='100' joint='right_shoulder1' />
        <motor name='right_shoulder2' gear='100' joint='right_shoulder2' />
        <motor name='right_elbow'     gear='200' joint='right_elbow' />
        <motor name='left_shoulder1'  gear='100' joint='left_shoulder1' />
        <motor name='left_shoulder2'  gear='100' joint='left_shoulder2' />
        <motor name='left_elbow'      gear='200' joint='left_elbow' />
    </actuator>

</mujoco>